tests/data/tight_spread.txt
N 1 B 99 47
N 2 B 98 26
C 1
N 3 S 101 37
C 3
N 4 S 98 52
P
N 5 B 99 86
C 5
N 6 B 99 2
N 7 S 102 60
N 8 B 102 27
B
C 6
B
N 9 B 99 85
N 10 S 101 2
N 11 B 99 6
N 12 S 98 93
P
C 12
N 13 B 99 4
C 9
N 14 B 101 29
N 15 S 98 90
C 15
C 14
N 16 B 100 29
N 17 S 101 23
N 18 S 101 2
P
C 17
N 19 S 100 35
N 20 B 102 47
N 21 S 101 21
N 22 B 99 100
N 23 S 98 92
N 24 B 99 17
N 25 S 99 58
N 26 B 98 40
N 27 S 99 29
N 28 S 98 13
C 27
N 29 B 101 83
N 30 S 99 74
C 26
N 31 S 98 99
B
C 24
N 32 S 102 4
N 33 S 99 97
N 34 S 101 84
N 35 S 98 34
C 25
N 36 B 98 90
N 37 B 100 74
N 38 B 100 20
P
N 39 B 101 18
N 40 S 99 56
N 41 S 98 69
N 42 S 102 37
N 43 B 101 6
B
N 44 S 100 48
N 45 B 98 58
P
P
C 44
N 46 S 98 33
C 43
N 47 B 100 71
N 48 S 101 16
C 35
N 49 B 101 76
N 50 S 98 20
N 51 S 100 24
N 52 S 99 94
N 53 S 100 17
N 54 B 98 38
N 55 B 102 45
C 45
N 56 B 99 31
N 57 B 101 65
P
N 58 B 102 12
B
N 59 B 102 75
N 60 S 99 20
N 61 B 101 30
N 62 S 100 56
N 63 B 102 14
N 64 S 99 98
N 65 S 100 5
N 66 S 102 65
N 67 S 100 14
N 68 S 101 63
C 53
P
P
N 69 B 99 85
P
N 70 S 101 86
C 32
N 71 S 102 83
N 72 B 102 91
N 73 B 102 54
N 74 B 100 51
B
N 75 B 98 57
C 38
N 76 S 100 88
C 46
N 77 B 100 49
C 51
C 49
B
N 78 B 100 90
N 79 S 101 88
C 68
N 80 B 101 36
P
N 81 S 98 47
N 82 B 101 18
N 83 S 98 48
N 84 S 98 72
C 29
N 85 S 99 43
N 86 B 100 18
C 71
N 87 B 102 66
B
C 63
N 88 S 99 61
C 7
N 89 B 102 10
N 90 B 101 97
N 91 B 99 99
C 67
N 92 S 102 37
N 93 B 99 11
C 92
N 94 B 98 1
N 95 B 100 96
N 96 S 99 27
N 97 S 101 38
C 56
N 98 B 102 92
N 99 S 99 31
N 100 S 102 54
N 101 S 100 85
P
B
N 102 S 102 78
N 103 B 99 64
N 104 S 102 55
N 105 B 101 83
N 106 B 98 10
B
N 107 B 100 19
B
N 108 S 101 53
N 109 S 98 27
C 34
P
C 47
N 110 S 98 95
B
N 111 B 99 10
N 112 S 102 91
C 30
P
C 108
P
C 20
C 28
N 113 S 99 3
P
N 114 B 98 2
N 115 B 99 8
N 116 B 98 21
C 36
C 112
N 117 S 98 95
N 118 S 102 44
N 119 S 100 18
N 120 S 100 13
N 121 B 99 77
N 122 S 98 93
N 123 B 98 67
C 97
C 96
N 124 B 100 98
N 125 B 100 83
N 126 S 99 98
P
N 127 B 101 29
N 128 S 99 89
N 129 B 101 20
N 130 S 102 34
N 131 S 99 10
N 132 B 99 17
N 133 S 101 88
N 134 S 100 16
N 135 S 100 81
P
N 136 B 99 60
N 137 S 101 78
N 138 S 102 41
N 139 B 98 59
N 140 S 102 14
C 75
N 141 B 99 73
N 142 B 98 79
N 143 S 98 73
P
N 144 B 101 18
N 145 B 100 56
N 146 B 99 27
C 89
C 99
N 147 S 98 4
N 148 S 99 66
N 149 S 98 48
N 150 S 99 20
N 151 B 100 38
N 152 S 100 93
N 153 B 99 10
N 154 B 102 37
N 155 B 100 43
C 80
C 37
C 149
N 156 B 99 96
N 157 B 102 32
B
N 158 B 98 43
N 159 S 102 61
N 160 S 100 70
N 161 B 98 4
N 162 S 98 29
C 18
N 163 B 101 52
N 164 S 100 10
N 165 B 102 46
B
N 166 S 101 10
P
N 167 B 99 24
C 144
B
N 168 B 100 19
P
N 169 S 100 54
P
N 170 B 98 18
C 113
N 171 S 102 90
C 57
C 126
N 172 S 100 85
N 173 S 102 15
N 174 S 99 23
N 175 S 98 65
C 173
N 176 B 101 55
N 177 B 101 21
N 178 B 101 50
N 179 S 98 17
N 180 B 102 63
N 181 S 102 58
C 61
N 182 S 98 5
N 183 S 102 79
N 184 B 102 100
N 185 B 100 39
N 186 B 102 6
N 187 S 100 15
N 188 S 100 9
N 189 B 101 64
N 190 S 98 90
N 191 S 101 42
C 177
N 192 B 99 39
C 167
N 193 S 100 73
N 194 B 101 4
C 94
N 195 S 101 15
C 79
N 196 B 101 54
N 197 B 98 49
N 198 S 99 4
C 78
N 199 S 102 71
N 200 S 100 77
P
N 201 B 100 32
N 202 B 102 6
N 203 S 98 75
N 204 S 101 73
N 205 S 101 18
N 206 S 100 64
C 4
N 207 B 100 32
C 22
N 208 S 99 20
N 209 B 101 83
N 210 S 99 2
C 178
N 211 S 101 10
N 212 B 98 1
P
N 213 B 101 34
C 62
C 31
N 214 S 100 76
N 215 S 100 93
N 216 B 102 2
N 217 B 99 75
C 188
N 218 B 99 3
N 219 S 101 34
N 220 S 98 56
N 221 S 99 47
N 222 S 102 60
N 223 B 99 25
N 224 S 99 12
C 54
N 225 B 102 47
C 121
N 226 B 98 59
C 145
P
N 227 S 101 4
C 148
N 228 S 100 47
N 229 B 100 97
N 230 B 101 79
N 231 S 101 41
N 232 S 98 48
C 104
B
N 233 B 98 19
N 234 S 100 3
N 235 S 98 25
P
N 236 S 99 80
C 141
N 237 B 101 18
N 238 S 101 92
N 239 B 99 95
N 240 B 101 82
N 241 S 99 74
N 242 B 99 18
P
C 86
N 243 B 101 22
C 10
N 244 B 100 5
N 245 B 100 61
N 246 S 102 60
N 247 S 100 36
N 248 S 99 34
C 227
N 249 S 100 7
N 250 S 99 67
N 251 S 101 56
N 252 B 100 2
N 253 B 101 99
C 190
N 254 B 101 5
N 255 S 99 23
N 256 B 99 10
N 257 S 102 49
N 258 B 100 13
C 111
N 259 B 99 62
B
N 260 B 98 36
N 261 S 100 45
N 262 S 100 78
N 263 B 99 19
N 264 B 100 49
N 265 S 99 83
N 266 B 98 27
B
N 267 S 101 8
N 268 S 101 65
C 162
B
N 269 S 102 89
C 136
N 270 B 98 56
C 154
N 271 S 102 92
N 272 B 102 26
C 197
N 273 S 98 92
N 274 B 98 23
N 275 S 99 55
N 276 B 102 85
N 277 S 98 86
P
N 278 B 99 53
P
N 279 S 98 35
N 280 S 99 53
N 281 B 101 88
N 282 B 102 97
N 283 B 99 42
N 284 S 99 31
N 285 S 98 60
N 286 S 102 99
N 287 B 98 77
N 288 S 100 53
N 289 B 101 98
N 290 B 98 64
N 291 S 100 5
N 292 B 101 10
N 293 S 100 72
C 236
C 105
N 294 S 98 95
N 295 S 98 2
B
N 296 B 99 72
N 297 S 100 76
N 298 S 99 94
C 64
N 299 B 100 94
C 203
N 300 B 98 36
N 301 S 99 93
C 128
N 302 B 102 80
N 303 S 98 75
N 304 S 100 92
P
N 305 B 98 50
N 306 S 102 24
N 307 B 99 8
N 308 B 100 9
N 309 S 99 7
N 310 B 101 32
N 311 B 101 38
N 312 B 98 54
B
B
N 313 B 101 57
N 314 B 100 87
C 311
N 315 S 100 1
N 316 S 99 62
N 317 S 98 82
N 318 S 102 93
N 319 S 100 95
N 320 S 100 36
N 321 B 102 11
N 322 B 98 9
C 202
P
N 323 B 102 40
N 324 B 99 10
N 325 B 100 91
C 179
N 326 B 99 14
C 122
N 327 B 99 99
N 328 S 99 24
P
N 329 B 101 96
C 225
N 330 S 102 47
C 228
N 331 S 99 79
N 332 S 98 5
N 333 S 101 81
C 91
N 334 S 98 1
N 335 S 98 89
N 336 S 102 26
N 337 S 102 60
N 338 B 102 82
C 251
C 2
P
N 339 S 100 9
C 174
N 340 S 100 12
P
N 341 S 101 77
C 333
C 176
N 342 B 101 15
N 343 S 98 53
N 344 S 100 16
N 345 B 101 12
N 346 S 101 85
N 347 S 100 88
B
N 348 B 99 10
N 349 B 98 68
C 65
N 350 B 100 5
N 351 B 102 63
N 352 B 100 66
N 353 S 100 80
B
N 354 B 98 59
N 355 B 99 44
N 356 S 98 10
N 357 B 100 26
B
N 358 B 102 45
N 359 S 101 46
N 360 S 100 79
N 361 B 98 85
B
C 261
P
N 362 B 100 1
N 363 B 99 39
N 364 B 98 54
C 93
N 365 B 102 37
N 366 S 100 31
C 216
N 367 B 101 18
C 42
N 368 S 100 70
C 277
N 369 S 98 63
N 370 S 98 27
C 98
N 371 S 100 58
N 372 S 98 47
N 373 B 101 98
N 374 B 99 22
N 375 S 101 65
N 376 S 98 2
N 377 B 98 61
N 378 B 102 58
N 379 S 98 4
N 380 S 99 19
N 381 B 98 18
P
N 382 B 102 95
N 383 B 98 90
N 384 S 99 27
N 385 B 100 42
N 386 S 101 18
N 387 S 99 94
N 388 B 99 10
N 389 B 102 29
N 390 S 98 33
N 391 B 100 76
N 392 S 100 78
N 393 S 100 2
N 394 B 99 66
N 395 S 102 55
N 396 S 102 79
N 397 B 102 48
N 398 S 100 59
N 399 S 101 50
N 400 B 101 29
C 290
N 401 B 102 37
N 402 S 101 96
N 403 S 101 15
C 327
N 404 B 99 16
B
N 405 S 100 27
C 123
N 406 S 98 37
B
N 407 B 98 35
N 408 S 98 31
B
C 39
N 409 S 98 56
N 410 S 98 93
N 411 B 102 66
N 412 S 99 87
C 275
N 413 B 101 90
N 414 S 99 43
N 415 S 101 87
N 416 S 101 20
B
C 132
B
N 417 B 100 63
N 418 S 101 31
N 419 S 101 28
N 420 S 102 1
N 421 B 99 81
N 422 S 100 94
C 223
B
N 423 S 99 32
N 424 B 102 30
N 425 S 99 45
N 426 B 101 89
C 250
N 427 S 98 79
N 428 S 98 34
C 124
N 429 B 100 35
N 430 S 101 8
N 431 B 101 81
B
N 432 B 98 61
P
B
N 433 B 101 5
N 434 S 99 45
N 435 S 98 4
C 370
N 436 S 102 3
N 437 B 100 29
C 246
C 21
N 438 B 100 38
P
P
N 439 B 100 72
N 440 S 102 27
N 441 S 99 36
N 442 B 100 65
C 205
C 316
C 213
N 443 S 99 57
N 444 B 98 41
N 445 S 102 41
N 446 S 100 87
N 447 B 98 7
N 448 B 100 26
B
C 287
N 449 B 102 83
N 450 S 100 61
C 286
C 298
N 451 B 99 29
N 452 B 100 24
N 453 B 100 44
N 454 S 98 15
N 455 B 101 35
N 456 S 99 27
C 170
P
N 457 S 102 11
N 458 B 99 97
N 459 B 98 3
N 460 B 98 26
N 461 B 98 65
N 462 B 100 30
N 463 B 101 82
N 464 B 99 49
N 465 S 102 34
P
N 466 B 102 57
C 423
N 467 B 101 26
N 468 S 99 83
N 469 B 101 78
C 33
N 470 B 99 1
N 471 B 100 23
N 472 S 101 78
N 473 S 101 26
N 474 S 100 27
N 475 S 98 84
N 476 S 102 96
N 477 S 100 7
C 226
N 478 S 98 42
N 479 S 102 79
N 480 S 99 96
C 284
C 134
N 481 B 100 35
P
N 482 B 102 57
P
N 483 B 101 42
N 484 B 101 24
N 485 S 99 86
C 180
N 486 B 99 42
C 314
N 487 S 98 40
N 488 B 100 7
P
N 489 S 100 43
N 490 B 101 23
N 491 B 98 4
C 101
N 492 S 99 38
N 493 B 102 73
N 494 S 100 1
N 495 S 100 87
C 435
C 360
C 475
B
N 496 S 99 77
C 110
N 497 S 102 38
C 318
C 321
C 88
N 498 B 98 53
