tests/data/tight_spread_expected.txt
ACK 1
ACK 2
CXL 1
ACK 3
CXL 3
ACK 4
TRD 2 4 98 26
TOB ASK 98 26
ACK 5
TRD 5 4 98 26
CXL 5
ACK 6
ACK 7
ACK 8
TRD 8 7 102 27
BOOK BID 99 2
BOOK ASK 102 33
CXL 6
BOOK ASK 102 33
ACK 9
ACK 10
ACK 11
ACK 12
TRD 9 12 99 85
TRD 11 12 99 6
TOB ASK 98 2
CXL 12
ACK 13
REJ 9 UNK
ACK 14
TRD 14 10 101 2
ACK 15
TRD 14 15 101 27
TRD 13 15 99 4
CXL 15
REJ 14 UNK
ACK 16
ACK 17
ACK 18
TOB BID 100 29
TOB ASK 101 25
CXL 17
ACK 19
TRD 16 19 100 29
ACK 20
TRD 20 19 100 6
TRD 20 18 101 2
TRD 20 7 102 33
ACK 21
TRD 20 21 102 6
ACK 22
ACK 23
TRD 22 23 99 92
ACK 24
ACK 25
TRD 22 25 99 8
TRD 24 25 99 17
ACK 26
ACK 27
ACK 28
TRD 26 28 98 13
CXL 27
ACK 29
TRD 29 25 99 33
TRD 29 21 101 15
ACK 30
TRD 29 30 101 35
CXL 26
ACK 31
BOOK ASK 98 99
BOOK ASK 99 39
REJ 24 UNK
ACK 32
ACK 33
ACK 34
ACK 35
REJ 25 UNK
ACK 36
TRD 36 31 98 90
ACK 37
TRD 37 31 98 9
TRD 37 35 98 34
TRD 37 30 99 31
ACK 38
TRD 38 30 99 8
TRD 38 33 99 12
TOB ASK 99 85
ACK 39
TRD 39 33 99 18
ACK 40
ACK 41
ACK 42
ACK 43
TRD 43 41 98 6
BOOK ASK 98 63
BOOK ASK 99 123
BOOK ASK 101 84
BOOK ASK 102 41
ACK 44
ACK 45
TRD 45 41 98 58
TOB ASK 98 5
TOB ASK 98 5
CXL 44
ACK 46
REJ 43 UNK
ACK 47
TRD 47 41 98 5
TRD 47 46 98 33
TRD 47 33 99 33
ACK 48
REJ 35 UNK
ACK 49
TRD 49 33 99 34
TRD 49 40 99 42
ACK 50
ACK 51
ACK 52
ACK 53
ACK 54
TRD 54 50 98 20
ACK 55
TRD 55 40 99 14
TRD 55 52 99 31
REJ 45 UNK
ACK 56
TRD 56 52 99 31
ACK 57
TRD 57 52 99 32
TRD 57 51 100 24
TRD 57 53 100 9
TOB BID 98 18
TOB ASK 100 8
ACK 58
TRD 58 53 100 8
TRD 58 34 101 4
BOOK BID 98 18
BOOK ASK 101 96
BOOK ASK 102 41
ACK 59
TRD 59 34 101 75
ACK 60
ACK 61
TRD 61 60 99 20
TRD 61 34 101 5
TRD 61 48 101 5
ACK 62
ACK 63
TRD 63 62 100 14
ACK 64
ACK 65
ACK 66
ACK 67
ACK 68
REJ 53 UNK
TOB BID 98 18
TOB ASK 99 98
TOB BID 98 18
TOB ASK 99 98
ACK 69
TRD 69 64 99 85
TOB BID 98 18
TOB ASK 99 13
ACK 70
CXL 32
ACK 71
ACK 72
TRD 72 64 99 13
TRD 72 62 100 42
TRD 72 65 100 5
TRD 72 67 100 14
TRD 72 48 101 11
TRD 72 68 101 6
ACK 73
TRD 73 68 101 54
ACK 74
BOOK BID 100 51
BOOK BID 98 18
BOOK ASK 101 89
BOOK ASK 102 185
ACK 75
REJ 38 UNK
ACK 76
TRD 74 76 100 51
REJ 46 UNK
ACK 77
TRD 77 76 100 37
REJ 51 UNK
REJ 49 UNK
BOOK BID 100 12
BOOK BID 98 75
BOOK ASK 101 89
BOOK ASK 102 185
ACK 78
ACK 79
CXL 68
ACK 80
TRD 80 70 101 36
TOB BID 100 102
TOB ASK 101 138
ACK 81
TRD 77 81 100 12
TRD 78 81 100 35
ACK 82
TRD 82 70 101 18
ACK 83
TRD 78 83 100 48
ACK 84
TRD 78 84 100 7
TRD 54 84 98 18
TRD 75 84 98 47
REJ 29 UNK
ACK 85
ACK 86
TRD 86 85 99 18
CXL 71
ACK 87
TRD 87 85 99 25
TRD 87 70 101 32
TRD 87 79 101 9
BOOK BID 98 10
BOOK ASK 101 79
BOOK ASK 102 102
REJ 63 UNK
ACK 88
REJ 7 UNK
ACK 89
TRD 89 88 99 10
ACK 90
TRD 90 88 99 51
TRD 90 79 101 46
ACK 91
REJ 67 UNK
ACK 92
ACK 93
CXL 92
ACK 94
ACK 95
ACK 96
TRD 95 96 100 27
ACK 97
REJ 56 UNK
ACK 98
TRD 98 79 101 33
TRD 98 97 101 38
TRD 98 42 102 21
ACK 99
TRD 95 99 100 31
ACK 100
ACK 101
TRD 95 101 100 38
TOB BID 99 110
TOB ASK 100 47
BOOK BID 99 110
BOOK BID 98 11
BOOK ASK 100 47
BOOK ASK 102 135
ACK 102
ACK 103
ACK 104
ACK 105
TRD 105 101 100 47
ACK 106
BOOK BID 101 36
BOOK BID 99 174
BOOK BID 98 21
BOOK ASK 102 268
ACK 107
BOOK BID 101 36
BOOK BID 100 19
BOOK BID 99 174
BOOK BID 98 21
BOOK ASK 102 268
ACK 108
TRD 105 108 101 36
ACK 109
TRD 107 109 100 19
TRD 91 109 99 8
REJ 34 UNK
TOB BID 99 166
TOB ASK 101 17
REJ 47 UNK
ACK 110
TRD 91 110 99 91
TRD 93 110 99 4
BOOK BID 99 71
BOOK BID 98 21
BOOK ASK 101 17
BOOK ASK 102 268
ACK 111
ACK 112
REJ 30 UNK
TOB BID 99 81
TOB ASK 101 17
CXL 108
TOB BID 99 81
TOB ASK 102 359
REJ 20 UNK
REJ 28 UNK
ACK 113
TRD 93 113 99 3
TOB BID 99 78
TOB ASK 102 359
ACK 114
ACK 115
ACK 116
REJ 36 UNK
CXL 112
ACK 117
TRD 93 117 99 4
TRD 103 117 99 64
TRD 111 117 99 10
TRD 115 117 99 8
TRD 75 117 98 9
ACK 118
ACK 119
ACK 120
ACK 121
ACK 122
TRD 121 122 99 77
TRD 75 122 98 1
TRD 94 122 98 1
TRD 106 122 98 10
TRD 114 122 98 2
TRD 116 122 98 2
ACK 123
REJ 97 UNK
REJ 96 UNK
ACK 124
TRD 124 119 100 18
TRD 124 120 100 13
ACK 125
ACK 126
TRD 124 126 100 67
TRD 125 126 100 31
TOB BID 100 52
TOB ASK 102 312
ACK 127
ACK 128
TRD 127 128 101 29
TRD 125 128 100 52
ACK 129
TRD 129 128 99 8
ACK 130
ACK 131
TRD 129 131 101 10
ACK 132
ACK 133
TRD 129 133 101 2
ACK 134
ACK 135
TOB BID 99 17
TOB ASK 100 97
ACK 136
ACK 137
ACK 138
ACK 139
ACK 140
REJ 75 UNK
ACK 141
ACK 142
ACK 143
TRD 132 143 99 17
TRD 136 143 99 56
TOB BID 99 77
TOB ASK 100 97
ACK 144
TRD 144 134 100 16
TRD 144 135 100 2
ACK 145
TRD 145 135 100 56
ACK 146
REJ 89 UNK
REJ 99 UNK
ACK 147
TRD 136 147 99 4
ACK 148
TRD 141 148 99 66
ACK 149
TRD 141 149 99 7
TRD 146 149 99 27
TRD 116 149 98 14
ACK 150
ACK 151
TRD 151 150 99 20
TRD 151 135 100 18
ACK 152
ACK 153
ACK 154
TRD 154 135 100 5
TRD 154 152 100 32
ACK 155
TRD 155 152 100 43
REJ 80 UNK
REJ 37 UNK
REJ 149 UNK
ACK 156
ACK 157
TRD 157 152 100 18
TRD 157 133 101 14
BOOK BID 99 106
BOOK BID 98 210
BOOK ASK 101 150
BOOK ASK 102 401
ACK 158
ACK 159
ACK 160
ACK 161
ACK 162
TRD 153 162 99 10
TRD 156 162 99 19
REJ 18 UNK
ACK 163
TRD 163 160 100 52
ACK 164
ACK 165
TRD 165 160 100 18
TRD 165 164 100 10
TRD 165 133 101 18
BOOK BID 99 77
BOOK BID 98 257
BOOK ASK 101 132
BOOK ASK 102 462
ACK 166
TOB BID 99 77
TOB ASK 101 142
ACK 167
REJ 144 UNK
BOOK BID 99 101
BOOK BID 98 257
BOOK ASK 101 142
BOOK ASK 102 462
ACK 168
TOB BID 100 19
TOB ASK 101 142
ACK 169
TRD 168 169 100 19
TOB BID 99 101
TOB ASK 100 35
ACK 170
REJ 113 UNK
ACK 171
REJ 57 UNK
REJ 126 UNK
ACK 172
ACK 173
ACK 174
TRD 156 174 99 23
ACK 175
TRD 156 175 99 54
TRD 167 175 99 11
CXL 173
ACK 176
TRD 176 169 100 35
TRD 176 172 100 20
ACK 177
TRD 177 172 100 21
ACK 178
TRD 178 172 100 44
TRD 178 133 101 6
ACK 179
TRD 167 179 99 13
TRD 116 179 98 4
ACK 180
TRD 180 133 101 48
TRD 180 137 101 15
ACK 181
REJ 61 UNK
ACK 182
TRD 116 182 98 1
TRD 123 182 98 4
ACK 183
ACK 184
TRD 184 137 101 63
TRD 184 166 101 10
TRD 184 42 102 16
TRD 184 66 102 11
ACK 185
ACK 186
TRD 186 66 102 6
ACK 187
TRD 185 187 100 15
ACK 188
TRD 185 188 100 9
ACK 189
ACK 190
TRD 189 190 101 64
TRD 185 190 100 15
TRD 123 190 98 11
ACK 191
REJ 177 UNK
ACK 192
REJ 167 UNK
ACK 193
ACK 194
TRD 194 193 100 4
REJ 94 UNK
ACK 195
REJ 79 UNK
ACK 196
TRD 196 193 100 54
ACK 197
ACK 198
TRD 192 198 99 4
REJ 78 UNK
ACK 199
ACK 200
TOB BID 99 35
TOB ASK 100 92
ACK 201
TRD 201 193 100 15
TRD 201 200 100 17
ACK 202
TRD 202 200 100 6
ACK 203
TRD 192 203 99 35
TRD 123 203 98 40
ACK 204
ACK 205
ACK 206
REJ 4 UNK
ACK 207
TRD 207 200 100 32
REJ 22 UNK
ACK 208
ACK 209
TRD 209 208 99 20
TRD 209 200 100 22
TRD 209 206 100 41
ACK 210
REJ 178 UNK
ACK 211
ACK 212
TOB BID 98 265
TOB ASK 99 2
ACK 213
TRD 213 210 99 2
TRD 213 206 100 23
TRD 213 191 101 9
REJ 62 UNK
REJ 31 UNK
ACK 214
ACK 215
ACK 216
TRD 216 214 100 2
ACK 217
REJ 188 UNK
ACK 218
ACK 219
ACK 220
TRD 217 220 99 56
ACK 221
TRD 217 221 99 19
TRD 218 221 99 3
ACK 222
ACK 223
TRD 223 221 99 25
ACK 224
REJ 54 UNK
ACK 225
TRD 225 224 99 12
TRD 225 214 100 35
REJ 121 UNK
ACK 226
REJ 145 UNK
TOB BID 98 324
TOB ASK 100 132
ACK 227
REJ 148 UNK
ACK 228
ACK 229
TRD 229 214 100 39
TRD 229 215 100 58
ACK 230
TRD 230 215 100 35
TRD 230 228 100 44
ACK 231
ACK 232
TRD 123 232 98 12
TRD 139 232 98 36
CXL 104
BOOK BID 98 276
BOOK ASK 100 3
BOOK ASK 101 228
BOOK ASK 102 732
ACK 233
ACK 234
ACK 235
TRD 139 235 98 23
TRD 142 235 98 2
TOB BID 98 270
TOB ASK 100 6
ACK 236
REJ 141 UNK
ACK 237
TRD 237 236 99 18
ACK 238
ACK 239
TRD 239 236 99 62
ACK 240
TRD 240 228 100 3
TRD 240 234 100 3
TRD 240 191 101 33
TRD 240 195 101 15
TRD 240 204 101 28
ACK 241
TRD 239 241 99 33
ACK 242
TRD 242 241 99 18
TOB BID 98 270
TOB ASK 99 23
REJ 86 UNK
ACK 243
TRD 243 241 99 22
REJ 10 UNK
ACK 244
TRD 244 241 99 1
ACK 245
ACK 246
ACK 247
TRD 244 247 100 4
TRD 245 247 100 32
ACK 248
TRD 245 248 100 29
CXL 227
ACK 249
ACK 250
ACK 251
ACK 252
TRD 252 248 99 2
ACK 253
TRD 253 248 99 3
TRD 253 250 99 67
TRD 253 249 100 7
TRD 253 204 101 22
REJ 190 UNK
ACK 254
TRD 254 204 101 5
ACK 255
ACK 256
TRD 256 255 99 10
ACK 257
ACK 258
TRD 258 255 99 13
REJ 111 UNK
ACK 259
BOOK BID 99 62
BOOK BID 98 270
BOOK ASK 101 269
BOOK ASK 102 841
ACK 260
